Workbook

Sheet Generalistes
A1: ID | B1: NomAffichage | C1: Titre | D1: Civilite | E1: PrenomOuInitiale | F1: Nom | G1: Structure | H1: Adresse1 | I1: Adresse2 | J1: CodePostal | K1: Ville | L1: Telephone | M1: BlocDestinataireComplet | N1: FormuleAppel | O1: TutoiementVouvoiement | P1: NombreOccurrences | Q1: SourceLignes | R1: Actif | S1: AValider | T1: CommentaireExtraction | U1: SourceInternet | V1: MethodeMiseAJour | W1: ID_Structure
A2: GEN_0001 | B2: Docteur Ahmed HASSANI | C2: Docteur | E2: Ahmed | F2: HASSANI | H2: 8, rue Jean Jaurès | J2: 60110 | K2: MÉRU | M2: Docteur Ahmed HASSANI 8, rue Jean Jaurès 60110 MÉRU | N2: Cher Ami, | O2: tu | P2: 1 | Q2: 2 | R2: Oui | S2: Oui
A3: GEN_0002 | B3: Docteur Ahmed OSMAAN | C3: Docteur | E3: Ahmed | F3: OSMAAN | H3: 88, Avenue du Général-de-Gaulle | J3: 95290 | K3: L’ISLE-ADAM | M3: Docteur Ahmed OSMAAN 88, Avenue du Général-de-Gaulle 95 290 L’Isle-Adam | N3: Cher Confrère, | O3: vous | P3: 1 | Q3: 3 | R3: Oui | S3: Oui
A4: GEN_0003 | B4: Docteur Farid AIT GANA | C4: Docteur | E4: Farid | F4: AIT GANA | H4: 10, Avenue du 8 mai 1945 | J4: 95400 | K4: VILLIERS LE BEL | M4: Docteur Farid AIT GANA 10, Avenue du 8 mai 1945 95400 VILLIERS LE BEL | N4: Cher Confrère, | O4: vous | P4: 1 | Q4: 4 | R4: Oui | S4: Oui | U4: https://www.sante.fr/medecine-generale/villiers-le-bel/dr-ait-gana-farid | V4: Vérifié en ligne le 02/08/2026
A5: GEN_0004 | B5: Docteur Alain TERMINET | C5: Docteur | E5: Alain | F5: TERMINET | H5: 5, rue du Bel Air | J5: 78570 | K5: ANDRÉSY | M5: Docteur Alain TERMINET 5, rue du Bel Air 78570 Andrésy | N5: Cher Confrère, | O5: vous | P5: 1 | Q5: 5 | R5: Oui | S5: Oui
A6: GEN_0005 | B6: Docteur Aline PAZAT-FROMENTIN | C6: Docteur | E6: Aline | F6: PAZAT-FROMENTIN | H6: 1, rue Jeanne Planche | J6: 95150 | K6: TAVERNY | M6: Docteur Aline PAZAT-FROMENTIN 1, rue Jeanne Planche 95150 Taverny | N6: Ma Chère Consoeur, | O6: vous | P6: 1 | Q6: 6 | R6: Oui | S6: Oui
A7: GEN_0006 | B7: Docteur ALLARDYCE James | C7: Docteur | E7: James | F7: ALLARDYCE | H7: 7 bis, rue Raymond Poincaré | J7: 95620 | K7: PARMAIN | M7: Docteur ALLARDYCE James 7 bis, rue Raymond Poincaré 95620 Parmain | N7: Mon Cher James, | O7: tu | P7: 2 | Q7: 7;81 | R7: Oui | S7: Oui
A8: GEN_0007 | B8: Docteur ALLAY François | C8: Docteur | E8: François | F8: ALLAY | H8: 22, place Tiburce-Lefèvre | J8: 60530 | K8: NEUILLY-EN-THELLE | M8: Docteur ALLAY François 22, place Tiburce-Lefèvre 60530 Neuilly-en-Thelle | N8: Cher Ami, | O8: tu | P8: 2 | Q8: 8;198 | R8: Oui | S8: Oui
A9: GEN_0008 | B9: Docteur Amine ROUIS | C9: Docteur | E9: Amine | F9: ROUIS | H9: 4, rue Léon Godin | J9: 95260 | K9: BEAUMONT-SUR-OISE | M9: Docteur Amine ROUIS 4, rue Léon Godin 95260 BEAUMONT-SUR-OISE | N9: Cher Ami, | O9: vous | P9: 1 | Q9: 9 | R9: Oui | S9: Oui | T9: Code postal et ville complétés en ligne. | U9: https://www.doctolib.fr/medecin-generaliste/beaumont-sur-oise/amine-rouis | V9: Vérifié en ligne le 02/08/2026
A10: GEN_0009 | B10: Docteur André SIDE | C10: Docteur | E10: André | F10: SIDE | H10: 47, avenue Paul-Valéry | J10: 95200 | K10: SARCELLES | M10: Docteur André SIDE 47, avenue Paul-Valéry 95 200 SARCELLES | N10: Cher Confrère, | O10: vous | P10: 1 | Q10: 10 | R10: Oui | S10: Oui
A11: GEN_0010 | B11: Docteur Anne LANKAR-KOBRYNER | C11: Docteur | E11: Anne | F11: LANKAR-KOBRYNER | H11: 56, rue de la Liberté | J11: 95470 | K11: SURVILLIERS | M11: Docteur Anne LANKAR-KOBRYNER 56, rue de la Liberté 95470 SURVILLIERS | N11: Ma Chère Consoeur, | O11: vous | P11: 1 | Q11: 11 | R11: Oui | S11: Oui | U11: https://www.sante.fr/medecine-generale/survilliers/dr-lankar-kobryner-anne | V11: Vérifié en ligne le 02/08/2026
A12: GEN_0011 | B12: Docteur Barbara TROUVÉ | C12: Docteur | E12: Barbara | F12: TROUVÉ | H12: 38, Sente Sorel | J12: 60460 | K12: PRÉCY-SUR-OISE | M12: Docteur Barbara TROUVÉ 38, Sente Sorel 60460 Précy-sur-Oise | N12: Ma Chère Amie, | O12: tu | P12: 5 | Q12: 12;13;14;15;16 | R12: Oui | S12: Oui
A13: GEN_0012 | B13: Docteur Sophie BEAUFRETON | C13: Docteur | E13: Sophie | F13: BEAUFRETON | H13: 5, impasse aux Cerfs | J13: 60580 | K13: COYE-LA-FORÊT | M13: Docteur Sophie BEAUFRETON 5, impasse aux Cerfs 60580 COYE-LA-FORÊT | N13: Cher Confrère, | O13: vous | P13: 1 | Q13: 17 | R13: Oui | S13: Oui | T13: Code postal corrigé de 65580 à 60580. | U13: https://www.sante.fr/medecine-generale/coye-la-foret/dr-beaufreton-sophie | V13: Vérifié en ligne le 02/08/2026
A14: GEN_0013 | B14: Docteur Zilassen BENBRAHIM | C14: Docteur | E14: Zilassen | F14: BENBRAHIM | H14: 16 rue de L’Isle-Adam | J14: 95260 | K14: BEAUMONT SUR OISE | M14: Docteur Zilassen BENBRAHIM 16 rue de L’Isle-Adam 95260 BEAUMONT SUR OISE | N14: Mon Très Cher Zilassen, | O14: tu | P14: 1 | Q14: 18 | R14: Oui | S14: Oui | V14: Prénom séparé du champ Nom existant le 02/08/2026
A15: GEN_0014 | B15: Docteur Bernard LADAM | C15: Docteur | E15: Bernard | F15: LADAM | H15: 4, Place de l’Église | J15: 60550 | K15: VERNEUIL-EN-HALATTE | M15: Docteur Bernard LADAM 4, Place de l’Église 60550 VERNEUIL-EN-HALATTE | N15: Cher Confrère, | O15: vous | P15: 1 | Q15: 19 | R15: Oui | S15: Oui
A16: GEN_0015 | B16: Docteur Nadia BERRABAH MAJDOUB | C16: Docteur | E16: Nadia | F16: BERRABAH MAJDOUB | H16: 10, avenue Paul Thoureau | J16: 95290 | K16: L’ISLE-ADAM | M16: Docteur Nadia BERRABAH MAJDOUB 10, avenue Paul Thoureau 95290 L’ISLE-ADAM | N16: Ma Chère Amie, | O16: vous | P16: 2 | Q16: 20;195 | R16: Oui | S16: Oui | V16: Prénom séparé du champ Nom existant le 02/08/2026
A17: GEN_0016 | B17: Docteur Delphine BLANPIED | C17: Docteur | E17: Delphine | F17: BLANPIED | H17: 3, Rue Kleinpeter | J17: 95270 | K17: VIARMES | M17: Docteur Delphine BLANPIED 3, Rue Kleinpeter 95270 VIARMES | N17: Ma Chère Amie, | O17: vous | P17: 2 | Q17: 21;43 | R17: Oui | S17: Oui | V17: Prénom séparé du champ Nom existant le 02/08/2026
A18: GEN_0017 | B18: Docteur Yacine BOUDJADJA | C18: Docteur | E18: Yacine | F18: BOUDJADJA | G18: Hôpital NOVO – Site de Beaumont-sur-Oise | H18: 25, rue Edmond Turcq | J18: 95260 | K18: BEAUMONT-SUR-OISE | M18: Docteur Yacine BOUDJADJA Hôpital NOVO – Site de Beaumont-sur-Oise 25, rue Edmond Turcq 95260 BEAUMONT-SUR-OISE | N18: Mon Cher Confrère, | O18: vous | P18: 1 | Q18: 22 | R18: Oui | S18: Oui | T18: Code postal et ville complétés en ligne. | U18: https://www.maquestionmedicale.fr/med-rdv/professions/medecin/beaumont-sur-oise/docteur-yacine-boudjadja.htm | V18: Vérifié en ligne le 02/08/2026 | W18: STR_0012
A19: GEN_0018 | B19: Docteur Catherine BREUILLARD-DORANGE | C19: Docteur | E19: Catherine | F19: BREUILLARD-DORANGE | H19: 12, rue Albert Dugué | J19: 60100 | K19: CREIL | M19: Docteur Catherine BREUILLARD-DORANGE 12, rue Albert Dugué 60100 CREIL | N19: Ma Chère Consoeur, | O19: vous | P19: 1 | Q19: 23 | R19: Oui | S19: Oui | U19: https://www.doctolib.fr/endocrinologue/creil/catherine-breuillard-dorange | V19: Vérifié en ligne le 02/08/2026
A20: GEN_0019 | B20: Docteur Camille HUMBERTCLAUDE | C20: Docteur | E20: Camille | F20: HUMBERTCLAUDE | H20: 9D, Rue Victor Hugo | J20: 60500 | K20: CHANTILLY | M20: Docteur Camille HUMBERTCLAUDE 9D, Rue Victor Hugo 60500 CHANTILLY | N20: Ma Chère Consoeur, | O20: vous | P20: 1 | Q20: 24 | R20: Oui | S20: Oui
A21: GEN_0020 | B21: Docteur Carole FESNEAU-DEZ | C21: Docteur | E21: Carole | F21: FESNEAU-DEZ | H21: 53, boulevard Léon Blum | J21: 95260 | K21: BEAUMONT-SUR-OISE | M21: Docteur Carole FESNEAU-DEZ 53, boulevard Léon Blum 95260 BEAUMONT-SUR-OISE | N21: Ma Chère Carole, | O21: tu | P21: 1 | Q21: 25 | R21: Oui | S21: Oui | T21: Nom complet et adresse actuelle vérifiés : FESNEAU-DEZ, 53 boulevard Léon Blum. | U21: https://www.sante.fr/medecine-generale/beaumont-sur-oise/dr-fesneau-dez-carole | V21: Vérifié en ligne le 02/08/2026
A22: GEN_0021 | B22: Docteur Carole GOURGAND | C22: Docteur | E22: Carole | F22: GOURGAND | H22: Maison de Santé | I22: 120, rue Raymond Joly | J22: 60230 | K22: CHAMBLY | M22: Docteur Carole GOURGAND Maison de Santé 120, rue Raymond Joly 60230 CHAMBLY | N22: Ma Chère Amie, | O22: vous | P22: 1 | Q22: 26 | R22: Oui | S22: Oui
A23: GEN_0022 | B23: Docteur Stéphanie CARTON | C23: Docteur | E23: Stéphanie | F23: CARTON | H23: 1, rue Ahmed Benkhaled | J23: 60250 | K23: MOUY | M23: Docteur Stéphanie CARTON 1, rue Ahmed Benkhaled 60250 MOUY | N23: Ma Chère Consoeur, | O23: vous | P23: 1 | Q23: 27 | R23: Oui | S23: Oui | U23: https://www.doctolib.fr/medecin-generaliste/mouy/stephanie-carton | V23: Vérifié en ligne le 02/08/2026
A24: GEN_0023 | B24: Docteur Catherine BOURGAIN | C24: Docteur | E24: Catherine | F24: BOURGAIN | H24: 5, Place de la Gare | J24: 95350 | K24: SAINT BRICE SOUS FORÊT | M24: Docteur Catherine BOURGAIN 5, Place de la Gare 95 350 SAINT BRICE SOUS FORÊT | N24: Ma Chère Consoeur, | O24: vous | P24: 1 | Q24: 28 | R24: Oui | S24: Oui
A25: GEN_0024 | B25: Docteur Catherine SOREL | C25: Docteur | E25: Catherine | F25: SOREL | H25: 30 bis, Grande Rue | J25: 67730 | K25: ULLY-SAINT-GEORGES | M25: Docteur Catherine SOREL 30 bis, Grande Rue 67730 Ully-Saint-Georges | N25: Ma Chère Consoeur, | O25: vous | P25: 2 | Q25: 29;131 | R25: Oui | S25: Oui
A26: GEN_0025 | B26: Docteur Cécile AMORY | C26: Docteur | E26: Cécile | F26: AMORY | H26: 25, avenue du Général Leclerc | J26: 60500 | K26: CHANTILLY | M26: Docteur Cécile AMORY 25, avenue du Général Leclerc 60500 Chantilly | N26: Ma Chère Consoeur, | O26: vous | P26: 1 | Q26: 30 | R26: Oui | S26: Oui
A27: GEN_0026 | B27: Docteur Céline BRETELLE | C27: Docteur | E27: Céline | F27: BRETELLE | H27: 5 bis, rue de l’Arrivée | J27: 95880 | K27: ENGHIEN-LES-BAINS | M27: Docteur Céline BRETELLE 5 bis, rue de l’Arrivée 95880 Enghien-les-Bains | N27: Ma Chère Consoeur, | O27: vous | P27: 1 | Q27: 31 | R27: Oui | S27: Oui
A28: GEN_0027 | B28: Docteur Céline PONCIN | C28: Docteur | E28: Céline | F28: PONCIN | H28: 10, place de la Garenne | J28: 95270 | K28: LUZARCHES | M28: Docteur Céline PONCIN 10, place de la Garenne 95270 Luzarches | N28: Ma Chère Consoeur, | O28: vous | P28: 2 | Q28: 32;33 | R28: Oui | S28: Oui
A29: GEN_0028 | B29: Docteur Nouradine CHIGRI | C29: Docteur | E29: Nouradine | F29: CHIGRI | H29: 3, Place de l’Église | J29: 60149 | K29: SAINT-CRÉPIN-IBOUVILLERS | M29: Docteur Nouradine CHIGRI 3, Place de l’Église 60149 SAINT-CRÉPIN-IBOUVILLERS | N29: Cher Confrère, | O29: vous | P29: 2 | Q29: 34;110 | R29: Oui | S29: Oui | V29: Prénom séparé du champ Nom existant le 02/08/2026
A30: GEN_0029 | B30: Docteur Claire BARBÉE | C30: Docteur | E30: Claire | F30: BARBÉE | H30: 5, Rue du Sétubal | J30: 60000 | K30: BEAUVAIS | M30: Docteur Claire BARBÉE 5, Rue du Sétubal 60000 BEAUVAIS | N30: Ma Chère Amie, | O30: vous | P30: 1 | Q30: 35 | R30: Oui | S30: Oui
A31: GEN_0030 | B31: Docteur Claire BELLEUDY | C31: Docteur | E31: Claire | F31: BELLEUDY | H31: 40, Rue Charles de Gaulle | J31: 95270 | K31: LUZARCHES | M31: Docteur Claire BELLEUDY 40, Rue Charles de Gaulle 95270 LUZARCHES | N31: Ma Chère Claire, | O31: vous | P31: 2 | Q31: 36;204 | R31: Oui | S31: Oui
A32: GEN_0031 | B32: Docteur Claudie DUVAL KUBACH | C32: Docteur | E32: Claudie | F32: DUVAL KUBACH | H32: 4 allée du 13-Août-1944 | J32: 60430 | K32: NOAILLES | M32: Docteur Claudie DUVAL KUBACH 4 allée du 13-Août-1944 60430 NOAILLES | N32: Ma Chère Amie, | O32: vous | P32: 3 | Q32: 37;38;58 | R32: Oui | S32: Oui
A33: GEN_0032 | B33: Docteur Ahmad SIMO | C33: Docteur | E33: Ahmad | F33: SIMO | H33: 3, chemin des Sources | J33: 95290 | K33: L’ISLE-ADAM | M33: Docteur Ahmad SIMO Clinique CONTI 3, chemin des Sources 95290 L’Isle-Adam | N33: Cher Ami, | O33: tu | P33: 1 | Q33: 39 | R33: Oui | S33: Oui
A34: GEN_0033 | B34: Docteur Daniel VANNAXAY | C34: Docteur | E34: Daniel | F34: VANNAXAY | H34: 24, rue Victor Basch | J34: 95190 | K34: GOUSSAINVILLE | M34: Docteur Daniel VANNAXAY 24, rue Victor Basch 95190 Goussainville | N34: Cher Confrère, | O34: vous | P34: 2 | Q34: 40;141 | R34: Oui | S34: Oui
A35: GEN_0034 | B35: Docteur William DEKESSUEDEM | C35: Docteur | E35: William | F35: DEKESSUEDEM | H35: 14 rue de Paris | J35: 95350 | K35: SAINT-BRICE-SOUS-FORÊT | M35: Docteur William DEKESSUEDEM 14 rue de Paris 95350 SAINT-BRICE-SOUS-FORÊT | N35: Cher Confrère, | O35: vous | P35: 1 | Q35: 41 | R35: Oui | S35: Oui | V35: Prénom séparé du champ Nom existant le 02/08/2026
A36: GEN_0035 | B36: Docteur Aline DELERUE | C36: Docteur | E36: Aline | F36: DELERUE | H36: 185 CHAUSSÉE TRAVERSIÈRE | J36: 60600 | K36: AGNETZ | M36: Docteur Aline DELERUE 185 CHAUSSÉE TRAVERSIÈRE 60600 AGNETZ | N36: Ma Chère Amie, | O36: vous | P36: 1 | Q36: 42 | R36: Oui | S36: Oui | V36: Prénom séparé du champ Nom existant le 02/08/2026
A37: GEN_0036 | B37: Docteur Denis MARTIN | C37: Docteur | E37: Denis | F37: MARTIN | H37: 37, rue du Général Empain | J37: 95570 | K37: BOUFFÉMONT | M37: Docteur Denis MARTIN 37, rue du Général Empain 95570 Bouffémont | N37: Cher Confrère, | O37: vous | P37: 1 | Q37: 44 | R37: Oui | S37: Oui
A38: GEN_0037 | B38: Docteur Diane BODEZ | C38: Docteur | E38: Diane | F38: BODEZ | H38: 32 avenue des Moulins Gémeaux | J38: 93207 | K38: SAINT-DENIS | M38: Docteur Diane BODEZ Centre Cardiologique du Nord 32 avenue des Moulins Gémeaux 93207 SAINT-DENIS | N38: Ma Chère Amie, | O38: vous | P38: 1 | Q38: 45 | R38: Oui | S38: Oui
A39: GEN_0038 | B39: Docteur Didier LECLERE | C39: Docteur | E39: Didier | F39: LECLERE | H39: 14 rue Jean Jaurès | J39: 60570 | K39: ANDEVILLE | M39: Docteur Didier LECLERE 14 rue Jean Jaurès 60570 ANDEVILLE | N39: Cher Ami, | O39: vous | P39: 2 | Q39: 46;47 | R39: Oui | S39: Oui
A40: GEN_0039 | B40: Docteur Didier PENNEROUX | C40: Docteur | E40: Didier | F40: PENNEROUX | H40: 80, rue Jean Jaurès | J40: 60570 | K40: ANDEVILLE | M40: Docteur Didier PENNEROUX 80, rue Jean Jaurès 60570 Andeville | N40: Mon Cher Didier, | O40: tu | P40: 3 | Q40: 48;206;253 | R40: Oui | S40: Oui
...

Sheet Specialistes
A1: ID | B1: TypeExamen | C1: TypesExamensPossibles | D1: NomDestinataire | E1: Titre | F1: Civilite | G1: PrenomOuInitiale | H1: Nom | I1: Structure | J1: Adresse1 | K1: Adresse2 | L1: CodePostal | M1: Ville | N1: Telephone | O1: BlocDestinataireComplet | P1: FormuleAppel | Q1: TutoiementVouvoiement | R1: Priorite | S1: Actif | T1: AValider | U1: CommentaireExtraction | V1: ID_Structure
A2: SPE_0001 | B2: SCINTIGRAPHIE_MYOCARDIQUE | C2: SCINTIGRAPHIE_MYOCARDIQUE;TEST_EFFORT | D2: HOPITAL PRIVE NORD PARISIEN | I2: HOPITAL PRIVE NORD PARISIEN | J2: SCINTIGRAPHIE | K2: 1 Avenue Charles Peguy | L2: 95200 | M2: SARCELLES | N2: 01 39 92 34 00 | O2: HOPITAL PRIVE NORD PARISIEN SCINTIGRAPHIE 1 Avenue Charles Peguy 95200 SARCELLES 01 39 92 34 00 | P2: Madame, Monsieur, | Q2: vous | R2: 1 | S2: Oui | T2: Oui | V2: STR_0015
A3: SPE_0002 | B3: COROSCANNER | C3: COROSCANNER;IRM | D3: Docteur Jacques FEIGNOUX | E3: Docteur | G3: Jacques | H3: FEIGNOUX | I3: Centre Cardiologique du Nord | J3: 32, avenue des Moulins Gémeaux | L3: 93207 | M3: SAINT-DENIS | O3: ANGIOSCANNER CORONAIRE Docteur Jacques FEIGNOUX Centre Cardiologique du Nord 32, avenue des Moulins Gémeaux 93207 SAINT-DENIS | P3: Mon Cher Jacques, | Q3: tu | R3: 1 | S3: Oui | T3: Non | U3: Complété par recoupement avec SPT_0003 et SPT_0021. | V3: STR_0003
A4: SPE_0003 | B4: TEST_EFFORT | C4: TEST_EFFORT;SCINTIGRAPHIE_MYOCARDIQUE;SCORE_CALCIQUE | D4: CARDILEC | I4: CARDILEC | J4: Centre Cardiologique du Val d'Oise | K4: 32, avenue Simone Veil | L4: 95520 | M4: OSNY | N4: 01 30 32 43 52 | O4: CARDILEC Centre Cardiologique du Val d'Oise 32, avenue Simone Veil 95520 OSNY Tel : 01 30 32 43 52 | P4: Madame, Monsieur, | Q4: vous | R4: 1 | S4: Oui | T4: Oui | V4: STR_0001
A5: SPE_0004 | B5: COROSCANNER | C5: COROSCANNER | D5: Centre Cardiologique du Nord | I5: Centre Cardiologique du Nord | J5: 32 avenue des Moulins Gémeaux | L5: 93207 | M5: SAINT-DENIS | O5: Centre Cardiologique du Nord 32 avenue des Moulins Gémeaux 93207 SAINT-DENIS | P5: Madame, Monsieur, | Q5: vous | R5: 1 | S5: Oui | T5: Oui | V5: STR_0003
A6: SPE_0005 | B6: TEST_EFFORT | C6: TEST_EFFORT;SCINTIGRAPHIE_MYOCARDIQUE;SCORE_CALCIQUE | D6: Clinique sainte Marie | I6: Clinique sainte Marie | J6: SCORE CALCIQUE | K6: 1 RUE Paul Emile Victor | L6: 95520 | M6: OSNY | N6: 01.30.17.49.64 | O6: Clinique sainte Marie SCORE CALCIQUE 1 RUE Paul Emile Victor 95520 OSNY 01.30.17.49.64 | P6: Madame, Monsieur, | Q6: vous | R6: 1 | S6: Oui | T6: Oui | V6: STR_0010
A7: SPE_0006 | B7: AVIS_DIABETOLOGIE | C7: AVIS_DIABETOLOGIE | D7: Docteur Abir JOSEPH | E7: Docteur | G7: Abir | H7: JOSEPH | I7: Clinique du Parc | J7: 23, rue des Frères Capucins | L7: 95310 | M7: SAINT-OUEN-L’AUMÔNE | O7: Docteur Abir JOSEPH Clinique du Parc 23, rue des Frères Capucins 95310 SAINT-OUEN-L’AUMÔNE | P7: Ma Chère Abir, | Q7: tu | R7: 1 | S7: Oui | T7: Non | U7: Complété par recoupement avec SPT_0011. | V7: STR_0009
A8: SPE_0007 | B8: AVIS_RYTHMOLOGIE | C8: AVIS_RYTHMOLOGIE | D8: Docteur Olivier PAZIAUD | E8: Docteur | G8: Olivier | H8: PAZIAUD | I8: Centre Cardiologique du Nord | J8: 32, avenue des Moulins Gémeaux | L8: 93207 | M8: SAINT-DENIS | O8: Docteur Olivier PAZIAUD Centre Cardiologique du Nord 32, avenue des Moulins Gémeaux 93207 SAINT-DENIS | P8: Mon Cher Olivier, | Q8: tu | R8: 1 | S8: Oui | T8: Non | U8: Complété par recoupement avec SPT_0012. | V8: STR_0003
A9: SPE_0008 | B9: AVIS_VASCULAIRE | C9: AVIS_VASCULAIRE | D9: Docteur Tonino PALOMBI | E9: Docteur | G9: Tonino | H9: PALOMBI | I9: Centre Cardiologique du Nord | J9: 32, avenue des Moulins Gémeaux | L9: 93207 | M9: SAINT-DENIS | O9: Docteur Tonino PALOMBI Centre Cardiologique du Nord 32, avenue des Moulins Gémeaux 93207 SAINT-DENIS | P9: Cher Ami, | Q9: tu | R9: 1 | S9: Oui | T9: Non | U9: Complété par recoupement avec SPT_0013. | V9: STR_0003
A10: SPE_0009 | B10: AVIS_GASTRO_ENTEROLOGIE | C10: AVIS_GASTRO_ENTEROLOGIE | D10: Docteur Pierre AKUE-GOEH | E10: Docteur | G10: Pierre | H10: AKUE-GOEH | I10: Clinique CONTI | J10: 3, chemin des Sources | L10: 95290 | M10: L’ISLE-ADAM | O10: Docteur Pierre AKUE-GOEH Clinique CONTI 3, chemin des Sources 95290 L’ISLE-ADAM | P10: Cher Ami, | Q10: tu | R10: 1 | S10: Oui | T10: Non | U10: Complété par recoupement avec SPT_0014. | V10: STR_0006
A11: SPE_0010 | B11: AVIS_RYTHMOLOGIE | C11: AVIS_RYTHMOLOGIE | D11: Docteur Olivier PIOT | E11: Docteur | G11: Olivier | H11: PIOT | I11: Centre Cardiologique du Nord | J11: 32, avenue des Moulins Gémeaux | L11: 93207 | M11: SAINT-DENIS | O11: Docteur Olivier PIOT Centre Cardiologique du Nord 32, avenue des Moulins Gémeaux 93207 SAINT-DENIS | P11: Mon Cher Olivier, | Q11: tu | R11: 2 | S11: Oui | T11: Non | U11: Complété par recoupement avec SPT_0015. | V11: STR_0003
A12: SPE_0011 | B12: AVIS_PNEUMOLOGIE | C12: AVIS_PNEUMOLOGIE | D12: Docteur Ahmad SIMO | E12: Docteur | G12: Ahmad | H12: SIMO | I12: Clinique CONTI | J12: 3, chemin des Sources | L12: 95290 | M12: L’ISLE-ADAM | O12: Docteur Ahmad SIMO Clinique CONTI 3, chemin des Sources 95290 L’ISLE-ADAM | P12: Cher Ami, | Q12: tu | R12: 1 | S12: Oui | T12: Non | U12: Complété par recoupement avec SPT_0016 et Generalistes. | V12: STR_0006
A13: SPE_0012 | B13: TEST_EFFORT | C13: TEST_EFFORT;SCINTIGRAPHIE_MYOCARDIQUE | D13: Hôpital Privé Nord Parisien | I13: Hôpital Privé Nord Parisien | J13: 2, Avenue Charles Peguy | L13: 95200 | M13: SARCELLES | O13: Hôpital Privé Nord Parisien 2, Avenue Charles Peguy 95200 SARCELLES | P13: Madame, Monsieur, | Q13: vous | R13: 1 | S13: Oui | T13: Oui | V13: STR_0015
A14: SPE_0013 | B14: SCORE_CALCIQUE | C14: SCORE_CALCIQUE | D14: Imagerie CANTILIEN | I14: Imagerie CANTILIEN | J14: Scanner - Score Calcique | K14: 12 avenue du Général LECLERC | L14: 60500 | M14: CHANTILLY | O14: Imagerie CANTILIEN Scanner - Score Calcique 12 avenue du Général LECLERC 60 500 CHANTILLY | P14: Madame, Monsieur, | Q14: vous | R14: 1 | S14: Oui | T14: Oui | V14: STR_0016
A15: SPE_0014 | B15: IRM | C15: IRM | D15: Docteur Juliette ROUSSEAU | E15: Docteur | G15: Juliette | H15: ROUSSEAU | I15: Centre Cardiologique du Nord | J15: 32, avenue des Moulins Gémeaux | L15: 93207 | M15: SAINT-DENIS | O15: IRM cardiaque de repos Docteur Juliette ROUSSEAU Centre Cardiologique du Nord 32, avenue des Moulins Gémeaux 93207 SAINT-DENIS | P15: Ma Chère Juliette, | Q15: tu | R15: 1 | S15: Oui | T15: Non | U15: Complété par recoupement avec SPT_0020 et Generalistes. | V15: STR_0003
A16: SPE_0015 | B16: SCINTIGRAPHIE_MYOCARDIQUE | C16: SCINTIGRAPHIE_MYOCARDIQUE;TEST_EFFORT | D16: SCINTIGRAPHIE PARIS-NORD | I16: SCINTIGRAPHIE PARIS-NORD | J16: Dr COHEN | K16: 1, avenue Charles-Péguy | L16: 95200 | M16: SARCELLES | N16: 01 39 92 34 00 | O16: SCINTIGRAPHIE PARIS-NORD Dr COHEN 1, avenue Charles-Péguy 95200 SARCELLES 01 39 92 34 00 | P16: Madame, Monsieur, | Q16: vous | R16: 1 | S16: Oui | T16: Oui | V16: STR_0019
A17: SPE_0016 | B17: SCINTIGRAPHIE_OSSEUSE | C17: SCINTIGRAPHIE_OSSEUSE | D17: SCINTIGRAPHIE PARIS-NORD | I17: SCINTIGRAPHIE PARIS-NORD | J17: scintigraphie osseuse | K17: 1 Avenue Charles Peguy | L17: 95200 | M17: SARCELLES | N17: 01 39 92 34 00 | O17: SCINTIGRAPHIE PARIS-NORD scintigraphie osseuse 1 Avenue Charles Peguy 95200 SARCELLES 01 39 92 34 00 | P17: Madame, Monsieur, | Q17: vous | R17: 1 | S17: Oui | T17: Oui | U17: Type d’examen corrigé par recoupement avec SPT_0005. | V17: STR_0019
A18: SPE_0017 | B18: SCORE_CALCIQUE | C18: SCORE_CALCIQUE | D18: CLINIQUE DES JOCKEYS | I18: Clinique des Jockeys | L18: 60500 | M18: CHANTILLY | O18: SCORE CALCIQUE Clinique des Jockeys 60500 CHANTILLY | P18: Mon Cher Confrère, | Q18: vous | R18: 3 | S18: Oui | T18: Non | U18: Code postal et ville complétés par recoupement avec SPT_0026. | V18: STR_0008
A19: SPE_0018 | B19: SCORE_CALCIQUE | C19: SCORE_CALCIQUE | D19: Score calcique | I19: Score calcique | J19: Clinique du parc | L19: 60000 | M19: BEAUVAIS | O19: Score calcique Clinique du parc 60 000 BEAUVAIS | P19: Madame, Monsieur, | Q19: vous | R19: 1 | S19: Oui | T19: Oui | V19: STR_0020
A20: SPE_0019 | B20: SCORE_CALCIQUE | C20: SCORE_CALCIQUE | D20: SERVICE D’IMAGERIE MÉDICALE – CLINIQUE SAINTE-MARIE | I20: Clinique Sainte-Marie | J20: 1, rue Paul-Émile-Victor | L20: 95520 | M20: OSNY | O20: SERVICE D’IMAGERIE MÉDICALE CLINIQUE SAINTE-MARIE 1, rue Paul-Émile-Victor 95520 OSNY | P20: Mon Cher Confrère, | Q20: vous | R20: 1 | S20: Oui | T20: Non | U20: Complété par recoupement avec SPT_0030. | V20: STR_0010
A21: SPE_0020 | B21: TESTS_GENETIQUES | C21: TESTS_GENETIQUES | D21: Service de génétique médicale | I21: Hôpital de la Pitié-Salpêtrière | J21: 47-83, boulevard de l’Hôpital | L21: 75013 | M21: PARIS | O21: Service de génétique médicale Hôpital de la Pitié-Salpêtrière 47-83, boulevard de l’Hôpital 75013 PARIS | P21: Mon Cher Confrère, | Q21: vous | R21: 1 | S21: Oui | T21: Non | U21: Complété par recoupement avec SPT_0031. | V21: STR_0014
A22: SPE_0021 | B22: A_COMPLETER | C22: A_COMPLETER | D22: CARDIO DÉPÔT | I22: CARDIO DÉPÔT | J22: 3 rue Théophraste Renaudot | L22: 54180 | M22: HOUDÉMONT | O22: CARDIO DÉPÔT 3 rue Théophraste Renaudot 54 180 HOUDÉMONT | P22: Madame, Monsieur, | Q22: vous | R22: 1 | S22: Oui | T22: Oui | U22: TypeExamen non déterminable par recoupement interne ; laissé à A_COMPLETER. | V22: STR_0002
A23: SPE_0022 | B23: ECHODOPPLER_VAISSEAUX_DU_COU | C23: ECHODOPPLER_VAISSEAUX_DU_COU;ECHODOPPLER_MEMBRES_INFERIEURS;ECHODOPPLER_VEINEUX;ECHODOPPLER_ARTERIEL | D23: Docteur Ara LOSHKAJIAN | E23: Docteur | G23: Ara | H23: LOSHKAJIAN | I23: Centre d’imagerie médicale | J23: Bâtiment C1 | K23: 13, rue Victor Hugo | L23: 60500 | M23: CHANTILLY | O23: ECHODOPPLER Docteur Ara LOSHKAJIAN Centre d’imagerie médicale Bâtiment C1 13, rue Victor Hugo 60500 CHANTILLY | P23: Cher Ami, | Q23: tu | R23: 1 | S23: Oui | T23: Non | U23: Complété par recoupement avec Generalistes GEN_0172 et Specialistes_ParType. | V23: STR_0004
A24: SPE_0022 | B24: ECHODOPPLER_MEMBRES_INFERIEURS | C24: ECHODOPPLER_VAISSEAUX_DU_COU;ECHODOPPLER_MEMBRES_INFERIEURS;ECHODOPPLER_VEINEUX;ECHODOPPLER_ARTERIEL | D24: Docteur Ara LOSHKAJIAN | E24: Docteur | G24: Ara | H24: LOSHKAJIAN | I24: Centre d’imagerie médicale | J24: Bâtiment C1 | K24: 13, rue Victor Hugo | L24: 60500 | M24: CHANTILLY | O24: ECHODOPPLER Docteur Ara LOSHKAJIAN Centre d’imagerie médicale Bâtiment C1 13, rue Victor Hugo 60500 CHANTILLY | P24: Cher Ami, | Q24: tu | R24: 1 | S24: Oui | T24: Non | U24: Complété par recoupement avec Generalistes GEN_0172 et Specialistes_ParType. | V24: STR_0004
A25: SPE_0022 | B25: ECHODOPPLER_VEINEUX | C25: ECHODOPPLER_VAISSEAUX_DU_COU;ECHODOPPLER_MEMBRES_INFERIEURS;ECHODOPPLER_VEINEUX;ECHODOPPLER_ARTERIEL | D25: Docteur Ara LOSHKAJIAN | E25: Docteur | G25: Ara | H25: LOSHKAJIAN | I25: Centre d’imagerie médicale | J25: Bâtiment C1 | K25: 13, rue Victor Hugo | L25: 60500 | M25: CHANTILLY | O25: ECHODOPPLER Docteur Ara LOSHKAJIAN Centre d’imagerie médicale Bâtiment C1 13, rue Victor Hugo 60500 CHANTILLY | P25: Cher Ami, | Q25: tu | R25: 1 | S25: Oui | T25: Non | U25: Complété par recoupement avec Generalistes GEN_0172 et Specialistes_ParType. | V25: STR_0004
A26: SPE_0022 | B26: ECHODOPPLER_ARTERIEL | C26: ECHODOPPLER_VAISSEAUX_DU_COU;ECHODOPPLER_MEMBRES_INFERIEURS;ECHODOPPLER_VEINEUX;ECHODOPPLER_ARTERIEL | D26: Docteur Ara LOSHKAJIAN | E26: Docteur | G26: Ara | H26: LOSHKAJIAN | I26: Centre d’imagerie médicale | J26: Bâtiment C1 | K26: 13, rue Victor Hugo | L26: 60500 | M26: CHANTILLY | O26: ECHODOPPLER Docteur Ara LOSHKAJIAN Centre d’imagerie médicale Bâtiment C1 13, rue Victor Hugo 60500 CHANTILLY | P26: Cher Ami, | Q26: tu | R26: 1 | S26: Oui | T26: Non | U26: Complété par recoupement avec Generalistes GEN_0172 et Specialistes_ParType. | V26: STR_0004
A27: SPE_0023 | B27: SAOS | C27: SAOS | D27: Docteur Samir MEDANE | E27: Docteur | F27: Monsieur | G27: Samir | H27: MEDANE | J27: 43 ter avenue Jean JAURES | L27: 95330 | M27: DOMONT | O27: Docteur Samir MEDANE 43 ter avenue Jean JAURES 95330 DOMONT | P27: Cher Confrère, | Q27: vous | R27: 1 | S27: Oui | T27: Non | U27: Créé par formulaire Word
A28: SPE_0024 | B28: SAOS | C28: SAOS | D28: Docteur Paul-Henri DEPOORTERE | E28: Docteur | F28: Monsieur | G28: Paul-Henri | H28: DEPOORTERE | J28: 10, Avenue Paul THOUREAU | L28: 95 290 | M28: L'ISLE ADAM | O28: Docteur Paul-Henri DEPOORTERE 10, Avenue Paul THOUREAU 95 290 L'ISLE ADAM | P28: Mon Cher Paul-Henri, | Q28: tu | R28: 100 | S28: Oui | T28: Non | U28: Créé par formulaire Word
A29: SPE_0025 | B29: SCANNER THORACIQUE sans injection | C29: SCANNER THORACIQUE sans injection | D29: Docteur . MONSIEUR LE RADIOLOGUE | E29: Docteur | F29: Monsieur | G29: . | H29: MONSIEUR LE RADIOLOGUE | I29: Clinique Sainte-Marie | J29: 1, rue Paul-Émile-Victor | L29: 95520 | M29: OSNY | N29: 01.30.17.49.64 | O29: Docteur . MONSIEUR LE RADIOLOGUE Clinique Sainte-Marie 1, rue Paul-Émile-Victor 95520 OSNY 01.30.17.49.64 | P29: Cher Confrère, | Q29: vous | R29: 1 | S29: Oui | T29: Non | U29: Créé par formulaire Word | V29: STR_0010

Sheet Specialistes_ParType
A1: ID_Ligne | B1: ID_Specialiste | C1: TypeExamen | D1: NomDestinataire | E1: Structure | F1: CodePostal | G1: Ville | H1: BlocDestinataireComplet | I1: FormuleAppel | J1: Priorite | K1: Actif | L1: AValider | M1: CleRegroupement | N1: FormulePolitesse | O1: TutoiementVouvoiement
A2: SPT_0015 | B2: SPE_0010 | C2: AVIS_RYTHMOLOGIE | D2: Docteur Olivier PIOT | E2: Centre Cardiologique du Nord 32, avenue des Moulins Gémeaux 93207 SAINT-DENIS | F2: 93207 | G2: SAINT-DENIS | H2: Docteur Olivier PIOT Centre Cardiologique du Nord 32, avenue des Moulins Gémeaux 93207 SAINT-DENIS | I2: Mon Cher Olivier, | J2: 2 | K2: Oui | L2: Non | M2: CCN_RYTHMOLOGIE_PIOT | N2: Amitiés. | O2: tu
A3: SPT_0012 | B3: SPE_0007 | C3: AVIS_RYTHMOLOGIE | D3: Docteur Olivier PAZIAUD | E3: Centre Cardiologique du Nord 32, avenue des Moulins Gémeaux 93207 SAINT-DENIS | F3: 93207 | G3: SAINT-DENIS | H3: Docteur Olivier PAZIAUD Centre Cardiologique du Nord 32 avenue des Moulins Gémeaux 93207 SAINT-DENIS | I3: Mon Cher Olivier, | J3: 1 | K3: Oui | L3: Non | M3: CCN_RYTHMOLOGIE_PAZIAUD | N3: Amitiés. | O3: tu
A4: SPT_0003 | B4: SPE_0002 | C4: COROSCANNER | D4: Docteur Jacques FEIGNOUX | E4: Centre Cardiologique du Nord 32, avenue des Moulins Gémeaux 93207 SAINT-DENIS | F4: 93207 | G4: SAINT-DENIS | H4: ANGIOSCANNER CORONAIRE Docteur Jacques FEIGNOUX Centre Cardiologique du Nord 32 avenue des Moulins Gémeaux 93207 SAINT-DENIS | I4: Mon Cher Jacques, | J4: 1 | K4: Oui | L4: Non | M4: CCN_COROSCANNER_FEIGNOUX | N4: Amitiés. | O4: tu
A5: SPT_0011 | B5: SPE_0006 | C5: AVIS_DIABETOLOGIE | D5: Docteur Abir JOSEPH | E5: Clinique Du PARC 23, Rue des Frères Capucins 95310 SAINT OUEN L'AUMONE | F5: 95310 | G5: SAINT OUEN L'AUMONE | H5: Docteur Abir JOSEPH Clinique Du PARC 23, Rue des Frères Capucins 95310 SAINT OUEN L'AUMONE | I5: Ma Chère Abir, | J5: 1 | K5: Oui | L5: Non | M5: CLINIQUE_DU_PARC_SAINT_OUEN | N5: Amitiés. | O5: tu
A6: SPT_0033 | B6: SPE_0022 | C6: ECHODOPPLER_VAISSEAUX_DU_COU | D6: Docteur Ara LOSHKAJIAN | E6: Centre d’imagerie médicale Bâtiment C1 13, rue Victor Hugo 60500 CHANTILLY | F6: 60500 | G6: CHANTILLY | H6: ECHODOPPLER Docteur Ara LOSHKAJIAN Centre d’imagerie médicale Bâtiment C1 13, rue Victor Hugo 60500 CHANTILLY | I6: Cher Ami, | J6: 1 | K6: Oui | L6: Non | M6: LOSHKAJIAN | N6: Amitiés. | O6: tu
A7: SPT_0014 | B7: SPE_0009 | C7: AVIS_GASTRO_ENTEROLOGIE | D7: Docteur Pierre AKUE-GOEH | E7: CLINIQUE CONTI 3, chemin des Sources 95290 L’Isle-Adam | F7: 95290 | G7: L’ISLE-ADAM | H7: Docteur Pierre AKUE-GOEH CLINIQUE CONTI 3, chemin des Sources 95290 L’Isle-Adam | I7: Cher Ami, | J7: 1 | K7: Oui | L7: Non | M7: CONTI_GASTRO_AKUE | N7: Amitiés. | O7: tu
A8: SPT_0021 | B8: SPE_0002 | C8: IRM | D8: Docteur Jacques FEIGNOUX | E8: Centre Cardiologique du Nord 32, avenue des Moulins Gémeaux 93207 SAINT-DENIS | F8: 93207 | G8: SAINT-DENIS | H8: IRM cardiaque de repos Docteur Jacques FEIGNOUX Centre Cardiologique du Nord 32, avenue des Moulins Gémeaux 93207 SAINT-DENIS | I8: Mon Cher Jacques, | J8: 2 | K8: Oui | L8: Non | M8: CCN_IRM_FEIGNOUX | N8: Amitiés. | O8: tu
A9: SPT_0020 | B9: SPE_0014 | C9: IRM | D9: Docteur Juliette ROUSSEAU | E9: Centre Cardiologique du Nord 32, avenue des Moulins Gémeaux 93207 SAINT-DENIS | F9: 93207 | G9: SAINT-DENIS | H9: IRM cardiaque de repos Docteur Juliette ROUSSEAU Centre Cardiologique du Nord 32, avenue des Moulins Gémeaux 93207 SAINT-DENIS | I9: Ma Chère Juliette, | J9: 1 | K9: Oui | L9: Non | M9: CCN_IRM_ROUSSEAU | N9: Amitiés. | O9: tu
A10: SPT_0016 | B10: SPE_0011 | C10: AVIS_PNEUMOLOGIE | D10: Docteur Ahmad SIMO | E10: CLINIQUE CONTI 3, chemin des Sources 95290 L’Isle-Adam | F10: 95290 | G10: L’ISLE-ADAM | H10: Docteur Ahmad SIMO Clinique CONTI 3, chemin des Sources 95290 L’ISLE-ADAM | I10: Cher Ami, | J10: 1 | K10: Oui | L10: Non | M10: CONTI_PNEUMO_SIMO | N10: Amitiés. | O10: tu
A11: SPT_0001 | B11: SPE_0001 | C11: SCINTIGRAPHIE_MYOCARDIQUE | D11: Docteur Joseph COHEN | E11: HOPITAL PRIVE NORD PARISIEN 2, Avenue Charles Peguy 95200 SARCELLES | F11: 95200 | G11: SARCELLES | H11: HOPITAL PRIVE NORD PARISIEN Docteur Joseph COHEN SCINTIGRAPHIE 2, Avenue Charles Peguy 95200 SARCELLES 01 39 92 34 00 | I11: Mon Très Cher Joseph, | J11: 1 | K11: Oui | L11: Non | M11: HPNP_SCINTIGRAPHIE_MYOCARDIQUE | N11: Amitiés. | O11: tu
A12: SPT_0005 | B12: SPE_0016 | C12: SCINTIGRAPHIE_OSSEUSE | D12: HOPITAL PRIVE NORD PARISIEN | E12: HOPITAL PRIVE NORD PARISIEN 2, Avenue Charles Peguy 95200 SARCELLES | F12: 95200 | G12: SARCELLES | H12: HOPITAL PRIVE NORD PARISIEN 2, Avenue Charles Peguy 95200 SARCELLES 01 39 92 34 00 | I12: Cher Ami, | J12: 1 | K12: Oui | L12: Non | M12: HPNP_SCINTIGRAPHIE_OSSEUSE | N12: Amitiés. | O12: tu
A13: SPT_0027 | B13: SPE_0018 | C13: SCORE_CALCIQUE | D13: CLINIQUE DU PARC | E13: Clinique du parc 60 000 BEAUVAIS | F13: 60000 | G13: BEAUVAIS | H13: Score calcique Clinique du parc 60 000 BEAUVAIS | I13: Mon Cher Confrère, | J13: 4 | K13: Oui | L13: Non | M13: CLINIQUE_DU_PARC_BEAUVAIS | N13: Bien cordialement. | O13: vous
... A24: SPT_0037 | B24: SPE_0023 | C24: SAOS | D24: Docteur Samir MEDANE | E24: 43 ter avenue Jean JAURES 95330 DOMONT | F24: 95330 | G24: DOMONT | H24: Docteur Samir MEDANE 43 ter avenue Jean JAURES 95330 DOMONT | I24: Cher Confrère, | J24: 1 | K24: Oui | L24: Non | M24: AUTO_SPE_0023 | N24: Bien cordialement. | O24: vous
A25: SPT_0038 | B25: SPE_0024 | C25: SAOS | D25: Docteur Paul-Henri DEPOORTERE | E25: 10? Avenue Paul THOUREAU 95 290 L'ISLE ADAM | F25: 95 290 | G25: L'ISLE ADAM | H25: Docteur Paul-Henri DEPOORTERE 10? Avenue Paul THOUREAU 95 290 L'ISLE ADAM | I25: Mon Cher Paul-Henri, | J25: 100 | K25: Oui | L25: Non | M25: AUTO_SPE_0024 | N25: Amitiés. | O25: tu
A26: SPT_0039 | B26: SPE_0025 | C26: SCANNER THORACIQUE sans injection | D26: Docteur . MONSIEUR LE RADIOLOGUE | E26: Clinique Sainte-Marie 1, rue Paul-Émile-Victor 95520 OSNY 01.30.17.49.64 | F26: 95520 | G26: OSNY | H26: Docteur . MONSIEUR LE RADIOLOGUE Clinique Sainte-Marie 1, rue Paul-Émile-Victor 95520 OSNY 01.30.17.49.64 | I26: Cher Confrère, | J26: 1 | K26: Oui | L26: Non | M26: AUTO_SPE_0025 | N26: Bien cordialement. | O26: vous

Sheet Listes
A1: Liste | B1: Valeur
A2: TypeExamen | B2: ECHODOPPLER_ARTERIEL
A3: TypeExamen | B3: ECHODOPPLER_VEINEUX
A4: TypeExamen | B4: ECHODOPPLER_VAISSEAUX_DU_COU
A5: TypeExamen | B5: ECHODOPPLER_MEMBRES_INFERIEURS
A6: TypeExamen | B6: TEST_EFFORT
A7: TypeExamen | B7: SCINTIGRAPHIE_MYOCARDIQUE
A8: TypeExamen | B8: SCINTIGRAPHIE_OSSEUSE
A9: TypeExamen | B9: COROSCANNER
A10: TypeExamen | B10: SCORE_CALCIQUE
A11: TypeExamen | B11: IRM
A12: TypeExamen | B12: AVIS_NEUROLOGIE
... A26: TutoiementVouvoiement | B26: vous

Sheet Mode_emploi
A1: Base de travail correspondants - v1
A3: Cette base a été générée automatiquement à partir des blocs destinataires fournis.
A4: Les colonnes AValider sont volontairement à Oui : il faut relire et corriger avant usage en production.
A6: Feuille Generalistes : base des correspondants des courriers principaux.
A7: Feuille Specialistes : base des correspondants/centres pour examens et avis.
A8: Feuille Specialistes_ParType : version dépliée, une ligne par type d'examen et destination, plus directement exploitable en VBA.
A9: Feuille Listes : valeurs standardisées pour validations et futures macros.
A11: Colonnes à corriger en priorité : FormuleAppel, TutoiementVouvoiement, TypeExamen/TypesExamensPossibles, Actif, AValider.
A12: Les adresses ou codes postaux non reconnus sont signalés dans CommentaireExtraction.
A14: Nouvelle feuille Structures : référentiel unique des établissements utilisables par le futur formulaire de saisie.
A15: ID_Structure sera la clé technique utilisée par le formulaire Word ; NomStructure sera affiché dans la liste déroulante.
A16: AValider=Oui signale une structure dont les données extraites sont ambiguës ou divergentes dans la base actuelle.
... A21: Le contrôle des doublons sera réalisé par VBA avant l'enregistrement définitif.

Sheet Structures
A1: ID_Structure | B1: NomStructure | C1: Adresse1 | D1: Adresse2 | E1: CodePostal | F1: Ville | G1: Telephone | H1: Actif | I1: AValider | J1: CleNormalisee | K1: SourceIDs | L1: Commentaire
A2: STR_0001 | B2: CARDILEC | C2: Centre Cardiologique du Val d'Oise | D2: 32, avenue Simone Veil | E2: 95520 | F2: OSNY | G2: 01 30 32 43 52 | H2: Oui | I2: Oui | J2: cardilec | K2: SPE_0003 | L2: La séparation structure/service/adresse mérite une validation.
A3: STR_0002 | B3: CARDIO DÉPÔT | C3: 3 rue Théophraste Renaudot | E3: 54180 | F3: HOUDÉMONT | H3: Oui | I3: Non | J3: cardio depot | K3: SPE_0021
A4: STR_0003 | B4: Centre Cardiologique du Nord | C4: 32 avenue des Moulins Gémeaux | E4: 93207 | F4: SAINT-DENIS | H4: Oui | I4: Non | J4: centre cardiologique du nord | K4: GEN_0053;SPE_0002;SPE_0004;SPE_0007;SPE_0008;SPE_0010;SPE_0014
A5: STR_0004 | B5: Centre d’imagerie médicale | C5: Bâtiment C1 | D5: 13, rue Victor Hugo | E5: 60500 | F5: CHANTILLY | H5: Oui | I5: Non | J5: centre d imagerie medicale | K5: SPE_0022
A6: STR_0005 | B6: Centre municipal de santé | C6: 9 Rue de la station | E6: 95130 | F6: FRANCONVILLE | H6: Oui | I6: Non | J6: centre municipal de sante | K6: GEN_0130
A7: STR_0006 | B7: Clinique CONTI | C7: 3, chemin des Sources | E7: 95290 | F7: L’ISLE-ADAM | H7: Oui | I7: Non | J7: clinique conti | K7: SPE_0009;SPE_0011
A8: STR_0007 | B8: Clinique de Domont | C8: 85, route de Domont | E8: 95330 | F8: DOMONT | H8: Oui | I8: Non | J8: clinique de domont | K8: GEN_0122
A9: STR_0008 | B9: Clinique des Jockeys | E9: 60500 | F9: CHANTILLY | H9: Oui | I9: Non | J9: clinique des jockeys | K9: SPE_0017
A10: STR_0009 | B10: Clinique du Parc | C10: 23, rue des Frères Capucins | E10: 95310 | F10: SAINT-OUEN-L’AUMÔNE | H10: Oui | I10: Non | J10: clinique du parc | K10: GEN_0076;SPE_0006
A11: STR_0010 | B11: Clinique Sainte-Marie | C11: 1, rue Paul-Émile-Victor | E11: 95520 | F11: OSNY | G11: 01.30.17.49.64 | H11: Oui | I11: Oui | J11: clinique sainte marie | K11: SPE_0005;SPE_0019 | L11: Données divergentes dans la base : SPE_0005: SCORE CALCIQUE | 1 RUE Paul Emile Victor | 95520 OSNY | 01.30.17.49.64 ; SPE_0019: 1, rue Paul-Émile-Victor | | 95520 OSNY |
A12: STR_0011 | B12: Hôpital Bertinot Juel | C12: 34 bis, rue Pierre Budin | E12: 60240 | F12: CHAUMONT-EN-VEXIN | H12: Oui | I12: Non | J12: hopital bertinot juel | K12: GEN_0071
A13: STR_0012 | B13: Hôpital NOVO – Site de Beaumont-sur-Oise | C13: 25, rue Edmond Turcq | E13: 95260 | F13: BEAUMONT-SUR-OISE | H13: Oui | I13: Non | J13: hopital novo site de beaumont sur oise | K13: GEN_0017
A14: STR_0013 | B14: Hôpital NOVO – Site de Pontoise | C14: 6 avenue de l’Ile de France | E14: 95300 | F14: PONTOISE | G14: 01.30.75.40.40 | H14: Oui | I14: Non | J14: hopital novo site de pontoise | K14: GEN_0045
A15: STR_0014 | B15: Hôpital de la Pitié-Salpêtrière | C15: 47-83, boulevard de l’Hôpital | E15: 75013 | F15: PARIS | H15: Oui | I15: Non | J15: hopital pitie salpetriere | K15: SPE_0020;GEN_0112
A16: STR_0015 | B16: Hôpital Privé Nord Parisien | C16: 2, Avenue Charles Peguy | E16: 95200 | F16: SARCELLES | G16: 01 39 92 34 00 | H16: Oui | I16: Oui | J16: hopital prive nord parisien | K16: SPE_0001;SPE_0012 | L16: Données divergentes dans la base : SPE_0001: SCINTIGRAPHIE | 1 Avenue Charles Peguy | 95200 SARCELLES | 01 39 92 34 00 ; SPE_0012: 2, Avenue Charles Peguy | | 95200 SARCELLES |
A17: STR_0016 | B17: Imagerie CANTILIEN | C17: Scanner - Score Calcique | D17: 12 avenue du Général LECLERC | E17: 60500 | F17: CHANTILLY | H17: Oui | I17: Oui | J17: imagerie cantilien | K17: SPE_0013 | L17: La séparation structure/service/adresse mérite une validation.
A18: STR_0017 | B18: Maison médicale des Vergers | C18: Centre commercial des Vergers | E18: 95350 | F18: SAINT-BRICE-SOUS-FORÊT | H18: Oui | I18: Non | J18: maison medicale des vergers | K18: GEN_0095
A19: STR_0018 | B19: RD 316 – Pôle de santé de Chaumontel | C19: Allée de la Poire de Bezy | E19: 95270 | F19: CHAUMONTEL | H19: Oui | I19: Non | J19: rd 316 pole de sante de chaumontel | K19: GEN_0198
A20: STR_0019 | B20: SCINTIGRAPHIE PARIS-NORD | C20: Dr COHEN | D20: 1, avenue Charles-Péguy | E20: 95200 | F20: SARCELLES | G20: 01 39 92 34 00 | H20: Oui | I20: Oui | J20: scintigraphie paris nord | K20: SPE_0015;SPE_0016 | L20: Données divergentes dans la base : SPE_0015: Dr COHEN | 1, avenue Charles-Péguy | 95200 SARCELLES | 01 39 92 34 00 ; SPE_0016: scintigraphie osseuse | 1 Avenue Charles Peguy | 95200 SARCELLES | 01 39 92 34 00 La séparation structure/service/adresse mérite une validation.
A21: STR_0020 | B21: Score calcique | C21: Clinique du parc | E21: 60000 | F21: BEAUVAIS | H21: Oui | I21: Oui | J21: score calcique | K21: SPE_0018 | L21: Nom issu du champ Structure mais semble correspondre à un examen/service ; à valider.
A22: STR_0021 | B22: Service d’hématologie – Hôpital NOVO, site de Pontoise | C22: 6, avenue de l’Île-de-France | E22: 95300 | F22: PONTOISE | H22: Oui | I22: Non | J22: service d hematologie hopital novo site de pontoise | K22: GEN_0065

Sheet Saisie_Correspondants
A1: SAISIE TECHNIQUE — NOUVEAU CORRESPONDANT
A3: CHAMPS SAISIS PAR LE FORMULAIRE | D3: CHAMPS CALCULÉS PAR EXCEL
A4: TypeCorrespondant | D4: Titre | E4: =IF(OR(TRIM(B6)<>"",TRIM(B7)<>""),"Docteur","")
A5: Sexe | D5: Civilite | E5: =IF(B5="Homme","Monsieur",IF(B5="Femme","Madame",""))
A6: Prenom | D6: NomAffichage | E6: =IF(TRIM(B7)="","",TRIM(E4&" "&B6&" "&UPPER(B7)))
A7: Nom | D7: NomDestinataire | E7: =IF(E6="","",E6)
A8: ID_Structure | D8: NomStructure | E8: =IF(B8="","",IFERROR(INDEX(Structures!$B$2:$B$499,MATCH(B8,Structures!$A$2:$A$499,0)),""))
A9: Adresse1Manuelle | D9: Adresse1Effective | E9: =IF(B9<>"",B9,IF(B8="","",IFERROR(INDEX(Structures!$C$2:$C$499,MATCH(B8,Structures!$A$2:$A$499,0))&"","")))
A10: Adresse2Manuelle | D10: Adresse2Effective | E10: =IF(B10<>"",B10,IF(B8="","",IFERROR(INDEX(Structures!$D$2:$D$499,MATCH(B8,Structures!$A$2:$A$499,0))&"","")))
A11: CodePostalManuel | D11: CodePostalEffectif | E11: =IF(B11<>"",B11,IF(B8="","",IFERROR(INDEX(Structures!$E$2:$E$499,MATCH(B8,Structures!$A$2:$A$499,0))&"","")))
A12: VilleManuelle | D12: VilleEffective | E12: =IF(B12<>"",B12,IF(B8="","",IFERROR(INDEX(Structures!$F$2:$F$499,MATCH(B8,Structures!$A$2:$A$499,0))&"","")))
A13: TelephoneManuel | D13: TelephoneEffectif | E13: =IF(B13<>"",B13,IF(B8="","",IFERROR(INDEX(Structures!$G$2:$G$499,MATCH(B8,Structures!$A$2:$A$499,0))&"","")))
A14: TutoiementVouvoiement | B14: vous | D14: FormuleAppel | E14: =IF(B16<>"",B16,IF(B14="tu",IF(B5="Femme","Ma Chère "&B6&",",IF(B5="Homme","Mon Cher "&B6&",","Cher Ami,")),IF(B5="Femme","Ma Chère Consoeur,","Cher Confrère,"))) -> Cher Confrère,
A15: TypesExamens | D15: FormulePolitesse | E15: =IF(B14="tu","Amitiés.","Bien cordialement.") -> Bien cordialement.
A16: FormuleAppelForcee | D16: BlocStructureComplet | E16: =IF(E8<>"",E8,"")&IF(E9<>"",IF(E8<>"",CHAR(10),"")&E9,"")&IF(E10<>"",CHAR(10)&E10,"")&IF(OR(E11<>"",E12<>""),CHAR(10)&TRIM(E11&" "&E12),"")&IF(E13<>"",CHAR(10)&E13,"")
D17: BlocDestinataireComplet | E17: =IF(E7="","",E7)&IF(E8<>"",CHAR(10)&E8,"")&IF(E9<>"",CHAR(10)&E9,"")&IF(E10<>"",CHAR(10)&E10,"")&IF(OR(E11<>"",E12<>""),CHAR(10)&TRIM(E11&" "&E12),"")&IF(E13<>"",CHAR(10)&E13,"")
D18: Actif | E18: ="Oui" -> Oui
D19: AValider | E19: ="Non" -> Non
D20: NombreOccurrences | E20: =0 -> 0
D21: MethodeMiseAJour | E21: ="Saisie formulaire Word - "&TEXT(TODAY(),"dd/mm/yyyy") -> #VALUE!
D22: TypeExamenPrincipal | E22: =IF(B15="","",IFERROR(LEFT(B15,FIND(";",B15)-1),B15))
D23: TypesExamensPossibles | E23: =IF(B15="","",B15)
D24: Priorite | E24: =1 -> 1
D25: CommentaireCreation | E25: ="Créé par formulaire Word" -> Créé par formulaire Word
D26: ID_Structure | E26: =IF(B8="","",B8)
A29: RÈGLES DU FUTUR FORMULAIRE WORD
A30: • | B30: La secrétaire choisira la structure dans une liste déroulante. Le formulaire enregistrera son ID technique dans B8.
A31: • | B31: Si aucune structure n'est sélectionnée, les champs d'adresse manuelle B9:B13 seront utilisés.
A32: • | B32: Le contrôle des doublons sera effectué par VBA avant toute écriture dans Generalistes ou Specialistes.
A33: • | B33: Pour un spécialiste, B15 recevra un ou plusieurs TypeExamen séparés par des points-virgules.
A34: • | B34: Une nouvelle structure sera créée dans Structures après contrôle de doublon, puis sélectionnée automatiquement.
A35: • | B35: Cette feuille sera masquée lorsque le formulaire sera définitivement validé.
